<?xml version="1.0" ?>
<!-- =================================================================================== -->
<!-- |    This document was autogenerated by xacro from lobsang_hexapod.xacro          | -->
<!-- |    EDITING THIS FILE BY HAND IS NOT RECOMMENDED                                 | -->
<!-- =================================================================================== -->
<!-- Revolute-Revolute Manipulator -->
<robot name="hexapod" xmlns:xacro="http://www.ros.org/wiki/xacro">
  <material name="black">
    <color rgba="0.0 0.0 0.0 1.0"/>
  </material>
  <material name="blue">
    <color rgba="0.0 0.0 0.8 1.0"/>
  </material>
  <material name="green">
    <color rgba="0.0 0.8 0.0 1.0"/>
  </material>
  <material name="grey">
    <color rgba="0.2 0.2 0.2 1.0"/>
  </material>
  <material name="orange">
    <color rgba="1.0 0.423529411765 0.0392156862745 1.0"/>
  </material>
  <material name="brown">
    <color rgba="0.870588235294 0.811764705882 0.764705882353 1.0"/>
  </material>
  <material name="red">
    <color rgba="0.8 0.0 0.0 1.0"/>
  </material>
  <material name="white">
    <color rgba="1.0 1.0 1.0 1.0"/>
  </material>
  <transmission name="tran1">
    <type>transmission_interface/SimpleTransmission</type>
    <joint name="front_left_body_coxa"/>
    <actuator name="motor1">
      <hardwareInterface>PositionJointInterface</hardwareInterface>
      <mechanicalReduction>1</mechanicalReduction>
    </actuator>
  </transmission>
  <transmission name="tran2">
    <type>transmission_interface/SimpleTransmission</type>
    <joint name="front_right_body_coxa"/>
    <actuator name="motor2">
      <hardwareInterface>PositionJointInterface</hardwareInterface>
      <mechanicalReduction>1</mechanicalReduction>
    </actuator>
  </transmission>
  <transmission name="tran3">
    <type>transmission_interface/SimpleTransmission</type>
    <joint name="front_left_coxa_femour"/>
    <actuator name="motor3">
      <hardwareInterface>PositionJointInterface</hardwareInterface>
      <mechanicalReduction>1</mechanicalReduction>
    </actuator>
  </transmission>
  <transmission name="tran4">
    <type>transmission_interface/SimpleTransmission</type>
    <joint name="front_right_coxa_femour"/>
    <actuator name="motor4">
      <hardwareInterface>PositionJointInterface</hardwareInterface>
      <mechanicalReduction>1</mechanicalReduction>
    </actuator>
  </transmission>
  <transmission name="tran5">
    <type>transmission_interface/SimpleTransmission</type>
    <joint name="front_left_femour_tibia"/>
    <actuator name="motor5">
      <hardwareInterface>PositionJointInterface</hardwareInterface>
      <mechanicalReduction>1</mechanicalReduction>
    </actuator>
  </transmission>
  <transmission name="tran6">
    <type>transmission_interface/SimpleTransmission</type>
    <joint name="front_right_femour_tibia"/>
    <actuator name="motor6">
      <hardwareInterface>PositionJointInterface</hardwareInterface>
      <mechanicalReduction>1</mechanicalReduction>
    </actuator>
  </transmission>
  <transmission name="tran7">
    <type>transmission_interface/SimpleTransmission</type>
    <joint name="middle_left_body_coxa"/>
    <actuator name="motor7">
      <hardwareInterface>PositionJointInterface</hardwareInterface>
      <mechanicalReduction>1</mechanicalReduction>
    </actuator>
  </transmission>
  <transmission name="tran8">
    <type>transmission_interface/SimpleTransmission</type>
    <joint name="middle_right_body_coxa"/>
    <actuator name="motor8">
      <hardwareInterface>PositionJointInterface</hardwareInterface>
      <mechanicalReduction>1</mechanicalReduction>
    </actuator>
  </transmission>
  <transmission name="tran9">
    <type>transmission_interface/SimpleTransmission</type>
    <joint name="middle_left_coxa_femour"/>
    <actuator name="motor9">
      <hardwareInterface>PositionJointInterface</hardwareInterface>
      <mechanicalReduction>1</mechanicalReduction>
    </actuator>
  </transmission>
  <transmission name="tran10">
    <type>transmission_interface/SimpleTransmission</type>
    <joint name="middle_right_coxa_femour"/>
    <actuator name="motor10">
      <hardwareInterface>PositionJointInterface</hardwareInterface>
      <mechanicalReduction>1</mechanicalReduction>
    </actuator>
  </transmission>
  <transmission name="tran11">
    <type>transmission_interface/SimpleTransmission</type>
    <joint name="middle_left_femour_tibia"/>
    <actuator name="motor11">
      <hardwareInterface>PositionJointInterface</hardwareInterface>
      <mechanicalReduction>1</mechanicalReduction>
    </actuator>
  </transmission>
  <transmission name="tran12">
    <type>transmission_interface/SimpleTransmission</type>
    <joint name="middle_right_femour_tibia"/>
    <actuator name="motor12">
      <hardwareInterface>PositionJointInterface</hardwareInterface>
      <mechanicalReduction>1</mechanicalReduction>
    </actuator>
  </transmission>
  <transmission name="tran13">
    <type>transmission_interface/SimpleTransmission</type>
    <joint name="rear_left_body_coxa"/>
    <actuator name="motor13">
      <hardwareInterface>PositionJointInterface</hardwareInterface>
      <mechanicalReduction>1</mechanicalReduction>
    </actuator>
  </transmission>
  <transmission name="tran14">
    <type>transmission_interface/SimpleTransmission</type>
    <joint name="rear_right_body_coxa"/>
    <actuator name="motor14">
      <hardwareInterface>PositionJointInterface</hardwareInterface>
      <mechanicalReduction>1</mechanicalReduction>
    </actuator>
  </transmission>
  <transmission name="tran15">
    <type>transmission_interface/SimpleTransmission</type>
    <joint name="rear_left_coxa_femour"/>
    <actuator name="motor15">
      <hardwareInterface>PositionJointInterface</hardwareInterface>
      <mechanicalReduction>1</mechanicalReduction>
    </actuator>
  </transmission>
  <transmission name="tran16">
    <type>transmission_interface/SimpleTransmission</type>
    <joint name="rear_right_coxa_femour"/>
    <actuator name="motor16">
      <hardwareInterface>PositionJointInterface</hardwareInterface>
      <mechanicalReduction>1</mechanicalReduction>
    </actuator>
  </transmission>
  <transmission name="tran17">
    <type>transmission_interface/SimpleTransmission</type>
    <joint name="rear_left_femour_tibia"/>
    <actuator name="motor17">
      <hardwareInterface>PositionJointInterface</hardwareInterface>
      <mechanicalReduction>1</mechanicalReduction>
    </actuator>
  </transmission>
  <transmission name="tran18">
    <type>transmission_interface/SimpleTransmission</type>
    <joint name="rear_right_femour_tibia"/>
    <actuator name="motor18">
      <hardwareInterface>PositionJointInterface</hardwareInterface>
      <mechanicalReduction>1</mechanicalReduction>
    </actuator>
  </transmission>
  <gazebo>
    <plugin filename="libgazebo_ros_control.so" name="gazebo_ros_control">
      <robotNamespace>/hexapod</robotNamespace>
    </plugin>
  </gazebo>
  <gazebo reference="base_link">
    <gravity>true</gravity>
    <material>Gazebo/White</material>
  </gazebo>
  <gazebo reference="front_left_tibia">
    <gravity>true</gravity>
    <mu1>10000</mu1>
    <mu2>10000</mu2>
    <material>Gazebo/Orange</material>
  </gazebo>
  <gazebo reference="front_right_tibia">
    <gravity>true</gravity>
    <mu1>10000</mu1>
    <mu2>10000</mu2>
    <material>Gazebo/Orange</material>
  </gazebo>
  <gazebo reference="middle_left_tibia">
    <gravity>true</gravity>
    <mu1>10000</mu1>
    <mu2>10000</mu2>
    <material>Gazebo/Orange</material>
  </gazebo>
  <gazebo reference="middle_right_tibia">
    <gravity>true</gravity>
    <mu1>10000</mu1>
    <mu2>10000</mu2>
    <material>Gazebo/Orange</material>
  </gazebo>
  <gazebo reference="rear_left_tibia">
    <gravity>true</gravity>
    <mu1>10000</mu1>
    <mu2>10000</mu2>
    <material>Gazebo/Orange</material>
  </gazebo>
  <gazebo reference="rear_right_tibia">
    <gravity>true</gravity>
    <mu1>10000</mu1>
    <mu2>10000</mu2>
    <material>Gazebo/Orange</material>
  </gazebo>
  <link name="base_link">
    <visual>
      <origin xyz="0 0 0"/>
      <geometry>
        <box size="0.241 0.141 0.044"/>
      </geometry>
      <material name="blue"/>
    </visual>
    <collision>
      <geometry>
        <!--<box size="0.2 0.1 0.05" />-->
        <box size="0.241 0.141 0.044"/>
      </geometry>
    </collision>
    <inertial>
      <origin rpy="0 0 0" xyz="0 0 0"/>
      <mass value="1.0"/>
      <inertia ixx="0.00364857222" ixy="5.215877e-05" ixz="0.00071534842" iyy="0.01507736897" iyz="-1.31077e-05" izz="0.01659310749"/>
    </inertial>
  </link>
  <link name="square">
    <visual>
      <origin xyz="0.0125 0 0"/>
      <geometry>
        <box size="0.025 0.025 0.025"/>
      </geometry>
      <material name="red_box">
        <color rgba=".5 0 0 1"/>
      </material>
    </visual>
    <collision>
      <geometry>
        <box size="0.025 0.025 0.025"/>
      </geometry>
    </collision>
    <inertial>
      <origin rpy="0 0 0" xyz="0 0 0"/>
      <mass value="1"/>
      <inertia ixx="0.00364857222" ixy="5.215877e-05" ixz="0.00071534842" iyy="0.01507736897" iyz="-1.31077e-05" izz="0.01659310749"/>
    </inertial>
  </link>  
  <joint name="base_link_square" type="fixed">
    <parent link="base_link"/>
    <child link="square"/>
    <origin rpy="0.0 0.0 0.0" xyz="0.1205 0 0"/>
  </joint>
  <link name="sensor_link">
    <visual>
      <origin xyz="0.0 0 0"/>
      <geometry>
        <box size="0 0 0"/>
      </geometry>      
    </visual>
    <collision>
      <geometry>
        <box size="0 0 0"/>
      </geometry>
    </collision>    
  </link>
  <joint name="square_sensor_link" type="fixed">
    <parent link="square"/>
    <child link="sensor_link"/>
    <origin rpy="0.0 0.0 0.0" xyz="0.025 0 0"/>
  </joint> 
  <link name="front_left_coxa">
    <visual>
      <origin rpy="0.0 0.0 0.0" xyz="0.03 0 0"/>
      <geometry>
        <box size="0.06 0.01 0.02"/>
      </geometry>
      <material name="green">
        <color rgba="0 .8 0 1"/>
      </material>
    </visual>
    <collision>
      <origin rpy="0.0 0.0 0.0" xyz="0.03 0 0"/>
      <geometry>
        <box size="0.06 0.01 0.02"/>
      </geometry>
    </collision>
    <inertial>
      <origin rpy="0 0 0" xyz="0 0 0"/>
      <mass value="0.3"/>
      <inertia ixx="0.00364857222" ixy="5.215877e-05" ixz="0.00071534842" iyy="0.01507736897" iyz="-1.31077e-05" izz="0.01659310749"/>
    </inertial>
  </link>
  <joint name="front_left_body_coxa" type="revolute">
    <axis xyz="0 0 1"/>
    <parent link="base_link"/>
    <child link="front_left_coxa"/>
    <origin rpy="0.0 0.0 0.785398163397" xyz="0.1205 0.0705 0"/>
    <limit effort="10" lower="-2.4" upper="2.4" velocity="3.14159265359"/>
    <dynamics damping="0.7"/>
  </joint>
  <link name="front_right_coxa">
    <visual>
      <origin rpy="0.0 0.0 0.0" xyz="0.03 0 0"/>
      <geometry>
        <box size="0.06 0.01 0.02"/>
      </geometry>
      <material name="green">
        <color rgba="0 .8 0 1"/>
      </material>
    </visual>
    <collision>
      <origin rpy="0.0 0.0 0.0" xyz="0.03 0 0"/>
      <geometry>
        <box size="0.06 0.01 0.02"/>
      </geometry>
    </collision>
    <inertial>
      <origin rpy="0 0 0" xyz="0 0 0"/>
      <mass value="0.3"/>
      <inertia ixx="0.00364857222" ixy="5.215877e-05" ixz="0.00071534842" iyy="0.01507736897" iyz="-1.31077e-05" izz="0.01659310749"/>
    </inertial>
  </link>
  <joint name="front_right_body_coxa" type="revolute">
    <axis xyz="0 0 1"/>
    <parent link="base_link"/>
    <child link="front_right_coxa"/>
    <origin rpy="0.0 0.0 -0.785398163397" xyz="0.1205 -0.0705 0"/>
    <limit effort="10" lower="-2.4" upper="2.4" velocity="3.14159265359"/>
    <dynamics damping="0.7"/>
  </joint>
  <link name="middle_left_coxa">
    <visual>
      <origin rpy="0.0 0.0 0.0" xyz="0.03 0 0"/>
      <geometry>
        <box size="0.06 0.01 0.02"/>
      </geometry>
      <material name="green">
        <color rgba="0 .8 0 1"/>
      </material>
    </visual>
    <collision>
      <origin rpy="0.0 0.0 0.0" xyz="0.03 0 0"/>
      <geometry>
        <box size="0.06 0.01 0.02"/>
      </geometry>
    </collision>
    <inertial>
      <origin rpy="0 0 0" xyz="0 0 0"/>
      <mass value="0.3"/>
      <inertia ixx="0.00364857222" ixy="5.215877e-05" ixz="0.00071534842" iyy="0.01507736897" iyz="-1.31077e-05" izz="0.01659310749"/>
    </inertial>
  </link>
  <joint name="middle_left_body_coxa" type="revolute">
    <axis xyz="0 0 1"/>
    <parent link="base_link"/>
    <child link="middle_left_coxa"/>
    <origin rpy="0.0 0.0 1.57079632679" xyz="0.0 0.1131 0"/>
    <limit effort="10" lower="-2.4" upper="2.4" velocity="3.14159265359"/>
    <dynamics damping="0.7"/>
  </joint>
  <link name="middle_right_coxa">
    <visual>
      <origin rpy="0.0 0.0 0.0" xyz="0.03 0 0"/>
      <geometry>
        <box size="0.06 0.01 0.02"/>
      </geometry>
      <material name="green">
        <color rgba="0 .8 0 1"/>
      </material>
    </visual>
    <collision>
      <origin rpy="0.0 0.0 0.0" xyz="0.03 0 0"/>
      <geometry>
        <box size="0.06 0.01 0.02"/>
      </geometry>
    </collision>
    <inertial>
      <origin rpy="0 0 0" xyz="0 0 0"/>
      <mass value="0.3"/>
      <inertia ixx="0.00364857222" ixy="5.215877e-05" ixz="0.00071534842" iyy="0.01507736897" iyz="-1.31077e-05" izz="0.01659310749"/>
    </inertial>
  </link>
  <joint name="middle_right_body_coxa" type="revolute">
    <axis xyz="0 0 1"/>
    <parent link="base_link"/>
    <child link="middle_right_coxa"/>
    <origin rpy="0.0 0.0 -1.57079632679" xyz="0.0 -0.1131 0.0"/>
    <limit effort="10" lower="-2.4" upper="2.4" velocity="3.14159265359"/>
    <dynamics damping="0.7"/>
  </joint>
  <link name="rear_left_coxa">
    <visual>
      <origin rpy="0.0 0.0 0.0" xyz="0.03 0 0"/>
      <geometry>
        <box size="0.06 0.01 0.02"/>
      </geometry>
      <material name="green">
        <color rgba="0 .8 0 1"/>
      </material>
    </visual>
    <collision>
      <origin rpy="0.0 0.0 0.0" xyz="0.03 0 0"/>
      <geometry>
        <box size="0.06 0.01 0.02"/>
      </geometry>
    </collision>
    <inertial>
      <origin rpy="0 0 0" xyz="0 0 0"/>
      <mass value="0.3"/>
      <inertia ixx="0.00364857222" ixy="5.215877e-05" ixz="0.00071534842" iyy="0.01507736897" iyz="-1.31077e-05" izz="0.01659310749"/>
    </inertial>
  </link>
  <joint name="rear_left_body_coxa" type="revolute">
    <axis xyz="0 0 1"/>
    <parent link="base_link"/>
    <child link="rear_left_coxa"/>
    <origin rpy="0.0 0.0 2.35619449019" xyz="-0.1205 0.0705 0"/>
    <limit effort="10" lower="-2.4" upper="2.4" velocity="3.14159265359"/>
    <dynamics damping="0.7"/>
  </joint>
  <link name="rear_right_coxa">
    <visual>
      <origin rpy="0.0 0.0 0.0" xyz="0.03 0 0"/>
      <geometry>
        <box size="0.06 0.01 0.02"/>
      </geometry>
      <material name="green">
        <color rgba="0 .8 0 1"/>
      </material>
    </visual>
    <collision>
      <origin rpy="0.0 0.0 0.0" xyz="0.03 0 0"/>
      <geometry>
        <box size="0.06 0.01 0.02"/>
      </geometry>
    </collision>
    <inertial>
      <origin rpy="0 0 0" xyz="0 0 0"/>
      <mass value="0.3"/>
      <inertia ixx="0.00364857222" ixy="5.215877e-05" ixz="0.00071534842" iyy="0.01507736897" iyz="-1.31077e-05" izz="0.01659310749"/>
    </inertial>
  </link>
  <joint name="rear_right_body_coxa" type="revolute">
    <axis xyz="0 0 1"/>
    <parent link="base_link"/>
    <child link="rear_right_coxa"/>
    <origin rpy="0.0 0.0 -2.35619449019" xyz="-0.1205 -0.0705 0"/>
    <limit effort="10" lower="-2.4" upper="2.4" velocity="3.14159265359"/>
    <dynamics damping="0.7"/>
  </joint>
  <link name="front_left_femour">
    <visual>
      <origin rpy="0.0 0.0 0" xyz="0.0418 0 0"/>
      <geometry>
        <box size="0.0836 0.02 0.01"/>
      </geometry>
      <material name="orange"/>
    </visual>
    <collision>
      <origin rpy="0.0 0.0 0.0" xyz="0.0418 0 0"/>
      <geometry>
        <box size="0.0836 0.02 0.01"/>
      </geometry>
    </collision>
    <inertial>
      <origin rpy="0 0 0" xyz="0.0 0 0"/>
      <mass value="0.3"/>
      <inertia ixx="0.00364857222" ixy="5.215877e-05" ixz="0.00071534842" iyy="0.01507736897" iyz="-1.31077e-05" izz="0.01659310749"/>
    </inertial>
  </link>
  <joint name="front_left_coxa_femour" type="revolute">
    <axis xyz="0 0 1"/>
    <parent link="front_left_coxa"/>
    <child link="front_left_femour"/>
    <origin rpy="1.57079632679489661923 0.0 0.0" xyz="0.06 0 0"/>
    <limit effort="10" lower="-2.4" upper="2.4" velocity="3.14159265359"/>
    <dynamics damping="0.7"/>
  </joint>
  <link name="front_right_femour">
    <visual>
      <origin rpy="0.0 0.0 0" xyz="0.0418 0 0"/>
      <geometry>
        <box size="0.0836 0.02 0.01"/>
      </geometry>
      <material name="orange"/>
    </visual>
    <collision>
      <origin rpy="0.0 0.0 0.0" xyz="0.0418 0 0"/>
      <geometry>
        <box size="0.0836 0.02 0.01"/>
      </geometry>
    </collision>
    <inertial>
      <origin rpy="0 0 0" xyz="0.0 0 0"/>
      <mass value="0.3"/>
      <inertia ixx="0.00364857222" ixy="5.215877e-05" ixz="0.00071534842" iyy="0.01507736897" iyz="-1.31077e-05" izz="0.01659310749"/>
    </inertial>
  </link>
  <joint name="front_right_coxa_femour" type="revolute">
    <axis xyz="0 0 1"/>
    <parent link="front_right_coxa"/>
    <child link="front_right_femour"/>
    <origin rpy="-1.57079632679489661923 0.0 0.0" xyz="0.06 0 0"/>
    <limit effort="10" lower="-2.4" upper="2.4" velocity="3.14159265359"/>
    <dynamics damping="0.7"/>
  </joint>
  <link name="middle_left_femour">
    <visual>
      <origin rpy="0.0 0.0 0" xyz="0.0418 0 0"/>
      <geometry>
        <box size="0.0836 0.02 0.01"/>
      </geometry>
      <material name="orange"/>
    </visual>
    <collision>
      <origin rpy="0.0 0.0 0.0" xyz="0.0418 0 0"/>
      <geometry>
        <box size="0.0836 0.02 0.01"/>
      </geometry>
    </collision>
    <inertial>
      <origin rpy="0 0 0" xyz="0.0 0 0"/>
      <mass value="0.3"/>
      <inertia ixx="0.00364857222" ixy="5.215877e-05" ixz="0.00071534842" iyy="0.01507736897" iyz="-1.31077e-05" izz="0.01659310749"/>
    </inertial>
  </link>
  <joint name="middle_left_coxa_femour" type="revolute">
    <axis xyz="0 0 1"/>
    <parent link="middle_left_coxa"/>
    <child link="middle_left_femour"/>
    <origin rpy="1.57079632679489661923 0.0 0.0" xyz="0.06 0 0"/>
    <limit effort="10" lower="-2.4" upper="2.4" velocity="3.14159265359"/>
    <dynamics damping="0.7"/>
  </joint>
  <link name="middle_right_femour">
    <visual>
      <origin rpy="0.0 0.0 0" xyz="0.0418 0 0"/>
      <geometry>
        <box size="0.0836 0.02 0.01"/>
      </geometry>
      <material name="orange"/>
    </visual>
    <collision>
      <origin rpy="0.0 0.0 0.0" xyz="0.0418 0 0"/>
      <geometry>
        <box size="0.0836 0.02 0.01"/>
      </geometry>
    </collision>
    <inertial>
      <origin rpy="0 0 0" xyz="0.0 0 0"/>
      <mass value="0.3"/>
      <inertia ixx="0.00364857222" ixy="5.215877e-05" ixz="0.00071534842" iyy="0.01507736897" iyz="-1.31077e-05" izz="0.01659310749"/>
    </inertial>
  </link>
  <joint name="middle_right_coxa_femour" type="revolute">
    <axis xyz="0 0 1"/>
    <parent link="middle_right_coxa"/>
    <child link="middle_right_femour"/>
    <origin rpy="-1.57079632679489661923 0.0 0.0" xyz="0.06 0 0"/>
    <limit effort="10" lower="-2.4" upper="2.4" velocity="3.14159265359"/>
    <dynamics damping="0.7"/>
  </joint>
  <link name="rear_left_femour">
    <visual>
      <origin rpy="0.0 0.0 0" xyz="0.0418 0 0"/>
      <geometry>
        <box size="0.0836 0.02 0.01"/>
      </geometry>
      <material name="orange"/>
    </visual>
    <collision>
      <origin rpy="0.0 0.0 0.0" xyz="0.0418 0 0"/>
      <geometry>
        <box size="0.0836 0.02 0.01"/>
      </geometry>
    </collision>
    <inertial>
      <origin rpy="0 0 0" xyz="0.0 0 0"/>
      <mass value="0.3"/>
      <inertia ixx="0.00364857222" ixy="5.215877e-05" ixz="0.00071534842" iyy="0.01507736897" iyz="-1.31077e-05" izz="0.01659310749"/>
    </inertial>
  </link>
  <joint name="rear_left_coxa_femour" type="revolute">
    <axis xyz="0 0 1"/>
    <parent link="rear_left_coxa"/>
    <child link="rear_left_femour"/>
    <origin rpy="1.57079632679489661923 0.0 0.0" xyz="0.06 0 0"/>
    <limit effort="10" lower="-2.4" upper="2.4" velocity="3.14159265359"/>
    <dynamics damping="0.7"/>
  </joint>
  <link name="rear_right_femour">
    <visual>
      <origin rpy="0.0 0.0 0" xyz="0.0418 0 0"/>
      <geometry>
        <box size="0.0836 0.02 0.01"/>
      </geometry>
      <material name="orange"/>
    </visual>
    <collision>
      <origin rpy="0.0 0.0 0.0" xyz="0.0418 0 0"/>
      <geometry>
        <box size="0.0836 0.02 0.01"/>
      </geometry>
    </collision>
    <inertial>
      <origin rpy="0 0 0" xyz="0.0 0 0"/>
      <mass value="0.3"/>
      <inertia ixx="0.00364857222" ixy="5.215877e-05" ixz="0.00071534842" iyy="0.01507736897" iyz="-1.31077e-05" izz="0.01659310749"/>
    </inertial>
  </link>
  <joint name="rear_right_coxa_femour" type="revolute">
    <axis xyz="0 0 1"/>
    <parent link="rear_right_coxa"/>
    <child link="rear_right_femour"/>
    <origin rpy="-1.57079632679489661923 0.0 0.0" xyz="0.06 0 0"/>
    <limit effort="10" lower="-2.4" upper="2.4" velocity="3.14159265359"/>
    <dynamics damping="0.7"/>
  </joint>
  <link name="front_left_tibia">
    <visual>
      <origin rpy="0.0 0.0 0.0" xyz="0.1 0 0"/>
      <geometry>
        <box size="0.2 0.01 0.01"/>
      </geometry>
      <material name="red"/>
    </visual>
    <collision>
      <origin rpy="0.0 0.0 0.0" xyz="0.1 0 0"/>
      <geometry>
        <box size="0.2 0.01 0.01"/>
      </geometry>
    </collision>
    <inertial>
      <origin rpy="0 0 0" xyz="0.0 0 0"/>
      <mass value="0.3"/>
      <inertia ixx="0.00364857222" ixy="5.215877e-05" ixz="0.00071534842" iyy="0.01507736897" iyz="-1.31077e-05" izz="0.01659310749"/>
    </inertial>
  </link>
  <joint name="front_left_femour_tibia" type="revolute">
    <axis xyz="0 0 1"/>
    <parent link="front_left_femour"/>
    <child link="front_left_tibia"/>
    <origin rpy="0.0 0.0 0.0" xyz="0.0836 0 0"/>
    <limit effort="10" lower="-2.4" upper="2.4" velocity="3.14159265359"/>
    <dynamics damping="0.7"/>
  </joint>
  <link name="front_right_tibia">
    <visual>
      <origin rpy="0.0 0.0 0.0" xyz="0.1 0 0"/>
      <geometry>
        <box size="0.2 0.01 0.01"/>
      </geometry>
      <material name="red"/>
    </visual>
    <collision>
      <origin rpy="0.0 0.0 0.0" xyz="0.1 0 0"/>
      <geometry>
        <box size="0.2 0.01 0.01"/>
      </geometry>
    </collision>
    <inertial>
      <origin rpy="0 0 0" xyz="0.0 0 0"/>
      <mass value="0.3"/>
      <inertia ixx="0.00364857222" ixy="5.215877e-05" ixz="0.00071534842" iyy="0.01507736897" iyz="-1.31077e-05" izz="0.01659310749"/>
    </inertial>
  </link>
  <joint name="front_right_femour_tibia" type="revolute">
    <axis xyz="0 0 1"/>
    <parent link="front_right_femour"/>
    <child link="front_right_tibia"/>
    <origin rpy="0.0 0.0 0.0" xyz="0.0836 0 0"/>
    <limit effort="10" lower="-2.4" upper="2.4" velocity="3.14159265359"/>
    <dynamics damping="0.7"/>
  </joint>
  <link name="middle_left_tibia">
    <visual>
      <origin rpy="0.0 0.0 0.0" xyz="0.1 0 0"/>
      <geometry>
        <box size="0.2 0.01 0.01"/>
      </geometry>
      <material name="red"/>
    </visual>
    <collision>
      <origin rpy="0.0 0.0 0.0" xyz="0.1 0 0"/>
      <geometry>
        <box size="0.2 0.01 0.01"/>
      </geometry>
    </collision>
    <inertial>
      <origin rpy="0 0 0" xyz="0.0 0 0"/>
      <mass value="0.3"/>
      <inertia ixx="0.00364857222" ixy="5.215877e-05" ixz="0.00071534842" iyy="0.01507736897" iyz="-1.31077e-05" izz="0.01659310749"/>
    </inertial>
  </link>
  <joint name="middle_left_femour_tibia" type="revolute">
    <axis xyz="0 0 1"/>
    <parent link="middle_left_femour"/>
    <child link="middle_left_tibia"/>
    <origin rpy="0.0 0.0 0.0" xyz="0.0836 0 0"/>
    <limit effort="10" lower="-2.4" upper="2.4" velocity="3.14159265359"/>
    <dynamics damping="0.7"/>
  </joint>
  <link name="middle_right_tibia">
    <visual>
      <origin rpy="0.0 0.0 0.0" xyz="0.1 0 0"/>
      <geometry>
        <box size="0.2 0.01 0.01"/>
      </geometry>
      <material name="red"/>
    </visual>
    <collision>
      <origin rpy="0.0 0.0 0.0" xyz="0.1 0 0"/>
      <geometry>
        <box size="0.2 0.01 0.01"/>
      </geometry>
    </collision>
    <inertial>
      <origin rpy="0 0 0" xyz="0.0 0 0"/>
      <mass value="0.3"/>
      <inertia ixx="0.00364857222" ixy="5.215877e-05" ixz="0.00071534842" iyy="0.01507736897" iyz="-1.31077e-05" izz="0.01659310749"/>
    </inertial>
  </link>
  <joint name="middle_right_femour_tibia" type="revolute">
    <axis xyz="0 0 1"/>
    <parent link="middle_right_femour"/>
    <child link="middle_right_tibia"/>
    <origin rpy="0.0 0.0 0.0" xyz="0.0836 0 0"/>
    <limit effort="10" lower="-2.4" upper="2.4" velocity="3.14159265359"/>
    <dynamics damping="0.7"/>
  </joint>
  <link name="rear_left_tibia">
    <visual>
      <origin rpy="0.0 0.0 0.0" xyz="0.1 0 0"/>
      <geometry>
        <box size="0.2 0.01 0.01"/>
      </geometry>
      <material name="red"/>
    </visual>
    <collision>
      <origin rpy="0.0 0.0 0.0" xyz="0.1 0 0"/>
      <geometry>
        <box size="0.2 0.01 0.01"/>
      </geometry>
    </collision>
    <inertial>
      <origin rpy="0 0 0" xyz="0.0 0 0"/>
      <mass value="0.3"/>
      <inertia ixx="0.00364857222" ixy="5.215877e-05" ixz="0.00071534842" iyy="0.01507736897" iyz="-1.31077e-05" izz="0.01659310749"/>
    </inertial>
  </link>
  <joint name="rear_left_femour_tibia" type="revolute">
    <axis xyz="0 0 1"/>
    <parent link="rear_left_femour"/>
    <child link="rear_left_tibia"/>
    <origin rpy="0.0 0.0 0.0" xyz="0.0836 0 0"/>
    <limit effort="10" lower="-2.4" upper="2.4" velocity="3.14159265359"/>
    <dynamics damping="0.7"/>
  </joint>
  <link name="rear_right_tibia">
    <visual>
      <origin rpy="0.0 0.0 0.0" xyz="0.1 0 0"/>
      <geometry>
        <box size="0.2 0.01 0.01"/>
      </geometry>
      <material name="red"/>
    </visual>
    <collision>
      <origin rpy="0.0 0.0 0.0" xyz="0.1 0 0"/>
      <geometry>
        <box size="0.2 0.01 0.01"/>
      </geometry>
    </collision>
    <inertial>
      <origin rpy="0 0 0" xyz="0.0 0 0"/>
      <mass value="0.3"/>
      <inertia ixx="0.00364857222" ixy="5.215877e-05" ixz="0.00071534842" iyy="0.01507736897" iyz="-1.31077e-05" izz="0.01659310749"/>
    </inertial>
  </link>
  <joint name="rear_right_femour_tibia" type="revolute">
    <axis xyz="0 0 1"/>
    <parent link="rear_right_femour"/>
    <child link="rear_right_tibia"/>
    <origin rpy="0.0 0.0 0.0" xyz="0.0836 0 0"/>
    <limit effort="10" lower="-2.4" upper="2.4" velocity="3.14159265359"/>
    <dynamics damping="0.7"/>
  </joint>
  <link name="front_left_end_effector">
    <visual>
      <origin rpy="0.0 0.0 0.0" xyz="0.0 0 0"/>
      <geometry>
        <box size="0.0 0.0 0.0"/>
      </geometry>
    </visual>
  </link>
  <joint name="front_left_tibia_virtual" type="fixed">
    <axis xyz="0 0 1"/>
    <parent link="front_left_tibia"/>
    <child link="front_left_end_effector"/>
    <origin rpy="0.0 0.0 0.0" xyz="0.2 0 0"/>
    <limit effort="10" lower="-2.4" upper="2.4" velocity="3.14159265359"/>
  </joint>
  <link name="front_right_end_effector">
    <visual>
      <origin rpy="0.0 0.0 0.0" xyz="0.0 0 0"/>
      <geometry>
        <box size="0.0 0.0 0.0"/>
      </geometry>
    </visual>
  </link>
  <joint name="front_right_tibia_virtual" type="fixed">
    <axis xyz="0 0 1"/>
    <parent link="front_right_tibia"/>
    <child link="front_right_end_effector"/>
    <origin rpy="0.0 0.0 0.0" xyz="0.2 0 0"/>
    <limit effort="10" lower="-2.4" upper="2.4" velocity="3.14159265359"/>
  </joint>
  <link name="middle_left_end_effector">
    <visual>
      <origin rpy="0.0 0.0 0.0" xyz="0.0 0 0"/>
      <geometry>
        <box size="0.0 0.0 0.0"/>
      </geometry>
    </visual>
  </link>
  <joint name="middle_left_tibia_virtual" type="fixed">
    <axis xyz="0 0 1"/>
    <parent link="middle_left_tibia"/>
    <child link="middle_left_end_effector"/>
    <origin rpy="0.0 0.0 0.0" xyz="0.2 0 0"/>
    <limit effort="10" lower="-2.4" upper="2.4" velocity="3.14159265359"/>
  </joint>
  <link name="middle_right_end_effector">
    <visual>
      <origin rpy="0.0 0.0 0.0" xyz="0.0 0 0"/>
      <geometry>
        <box size="0.0 0.0 0.0"/>
      </geometry>
    </visual>
  </link>
  <joint name="middle_right_tibia_virtual" type="fixed">
    <axis xyz="0 0 1"/>
    <parent link="middle_right_tibia"/>
    <child link="middle_right_end_effector"/>
    <origin rpy="0.0 0.0 0.0" xyz="0.2 0 0"/>
    <limit effort="10" lower="-2.4" upper="2.4" velocity="3.14159265359"/>
  </joint>
  <link name="rear_left_end_effector">
    <visual>
      <origin rpy="0.0 0.0 0.0" xyz="0.0 0 0"/>
      <geometry>
        <box size="0.0 0.0 0.0"/>
      </geometry>
    </visual>
  </link>
  <joint name="rear_left_tibia_virtual" type="fixed">
    <axis xyz="0 0 1"/>
    <parent link="rear_left_tibia"/>
    <child link="rear_left_end_effector"/>
    <origin rpy="0.0 0.0 0.0" xyz="0.2 0 0"/>
    <limit effort="10" lower="-2.4" upper="2.4" velocity="3.14159265359"/>
  </joint>
  <link name="rear_right_end_effector">
    <visual>
      <origin rpy="0.0 0.0 0.0" xyz="0.0 0 0"/>
      <geometry>
        <box size="0.0 0.0 0.0"/>
      </geometry>
    </visual>
  </link>
  <joint name="rear_right_tibia_virtual" type="fixed">
    <axis xyz="0 0 1"/>
    <parent link="rear_right_tibia"/>
    <child link="rear_right_end_effector"/>
    <origin rpy="0.0 0.0 0.0" xyz="0.2 0 0"/>
    <limit effort="10" lower="-2.4" upper="2.4" velocity="3.14159265359"/>
  </joint>
</robot>

