<?xml version="1.0" ?>
<robot name="myrobot">
   <link name="world" />
   <link name="base_link">
    <visual>
      <origin xyz="0 0 0"/>
      <geometry>
        <box size="0.241 0.141 0.044"/>
      </geometry>
      <material name="blue"/>
    </visual>
    <collision>
      <geometry>
        <!--<box size="0.2 0.1 0.05" />-->
        <box size="0.241 0.141 0.044"/>
      </geometry>
    </collision>
    <inertial>
      <origin rpy="0 0 0" xyz="0 0 0"/>
      <mass value="1.0"/>
      <inertia ixx="0.00364857222" ixy="5.215877e-05" ixz="0.00071534842" iyy="0.01507736897" iyz="-1.31077e-05" izz="0.01659310749"/>
    </inertial>
  </link>
  <joint name="a00" type="fixed">
    <parent link="world"/>
    <child link="base_link"/>
    <origin rpy="0 0 0.0" xyz="0 0 0"/>
    <axis xyz="0 0 0"/>
    <limit effort="150" lower="-300000" upper="3000000" velocity="150000000"/>
  </joint> 
  
  <!--link name="square">
    <visual>
      <origin xyz="0.0125 0 0"/>
      <geometry>
        <box size="0.025 0.025 0.025"/>
      </geometry>
      <material name="red_box">
        <color rgba=".5 0 0 1"/>
      </material>
    </visual>
    <collision>
      <geometry>
        <box size="0.025 0.025 0.025"/>
      </geometry>
    </collision>
    <inertial>
      <origin rpy="0 0 0" xyz="0 0 0"/>
      <mass value="1"/>
      <inertia ixx="0.00364857222" ixy="5.215877e-05" ixz="0.00071534842" iyy="0.01507736897" iyz="-1.31077e-05" izz="0.01659310749"/>
    </inertial>
  </link> 
  
  <joint name="a01" type="fixed">
    <parent link="base_link"/>
    <child link="square"/>
    <origin rpy="0.0 0.0 0.0" xyz="0.1205 0 0"/>
  </joint-->
  
  <!--link name="sensor_link">
    <visual>
      <origin xyz="0.0 0 0"/>
      <geometry>
        <box size="0 0 0"/>
      </geometry>      
    </visual>
    <collision>
      <geometry>
        <box size="0 0 0"/>
      </geometry>
    </collision>    
  </link>
  <joint name="a03" type="fixed">
    <parent link="square"/>
    <child link="sensor_link"/>
    <origin rpy="0.0 0.0 0.0" xyz="0.025 0 0"/>
  </joint--> 
  
  <link name="front_left_coxa">
    <visual>
      <origin rpy="0.0 0.0 0.0" xyz="0.03 0 0"/>
      <geometry>
        <box size="0.06 0.01 0.02"/>
      </geometry>
      <material name="green">
        <color rgba="0 .8 0 1"/>
      </material>
    </visual>
    <collision>
      <origin rpy="0.0 0.0 0.0" xyz="0.03 0 0"/>
      <geometry>
        <box size="0.06 0.01 0.02"/>
      </geometry>
    </collision>
    <inertial>
      <origin rpy="0 0 0" xyz="0.03 0 0"/>
      <mass value="0.3"/>
      <inertia ixx="0.00364857222" ixy="5.215877e-05" ixz="0.00071534842" iyy="0.01507736897" iyz="-1.31077e-05" izz="0.01659310749"/>
    </inertial>    
  </link>
  
  <joint name="a01" type="revolute">
    <axis xyz="0 0 1"/>
    <parent link="base_link"/>
    <child link="front_left_coxa"/>
    <origin rpy="0.0 0.0 0.785398163397" xyz="0.1205 0.0705 0"/>    
    <limit effort="150" lower="-300000" upper="3000000" velocity="150000000"/>
    <dynamics damping="0.7"/>
  </joint>
  
  <link name="front_right_coxa">
    <visual>
      <origin rpy="0.0 0.0 0.0" xyz="0.03 0 0"/>
      <geometry>
        <box size="0.06 0.01 0.02"/>
      </geometry>
      <material name="green">
        <color rgba="0 .8 0 1"/>
      </material>
    </visual>
    <collision>
      <origin rpy="0.0 0.0 0.0" xyz="0.03 0 0"/>
      <geometry>
        <box size="0.06 0.01 0.02"/>
      </geometry>
    </collision>
    <inertial>
      <origin rpy="0 0 0" xyz="0.03 0 0"/>
      <mass value="0.3"/>
      <inertia ixx="0.00364857222" ixy="5.215877e-05" ixz="0.00071534842" iyy="0.01507736897" iyz="-1.31077e-05" izz="0.01659310749"/>
    </inertial>    
  </link>
  
  <joint name="a02" type="revolute">
    <axis xyz="0 0 1"/>
    <parent link="base_link"/>
    <child link="front_right_coxa"/>
    <origin rpy="0.0 0.0 -0.785398163397" xyz="0.1205 -0.0705 0"/>    
    <limit effort="150" lower="-300000" upper="3000000" velocity="150000000"/>
    <dynamics damping="0.7"/>
  </joint>
  
  <!--link name="middle_left_coxa">
    <visual>
      <origin rpy="0.0 0.0 0.0" xyz="0.03 0 0"/>
      <geometry>
        <box size="0.06 0.01 0.02"/>
      </geometry>
      <material name="green">
        <color rgba="0 .8 0 1"/>
      </material>
    </visual>
    <collision>
      <origin rpy="0.0 0.0 0.0" xyz="0.03 0 0"/>
      <geometry>
        <box size="0.06 0.01 0.02"/>
      </geometry>
    </collision>
    <inertial>
      <origin rpy="0 0 0" xyz="0.03 0 0"/>
      <mass value="0.3"/>
      <inertia ixx="0.00364857222" ixy="5.215877e-05" ixz="0.00071534842" iyy="0.01507736897" iyz="-1.31077e-05" izz="0.01659310749"/>
    </inertial>    
  </link>
  
  <joint name="j02" type="revolute">
    <axis xyz="0 0 1"/>
    <parent link="base_link"/>
    <child link="middle_left_coxa"/>
    <origin rpy="0.0 0.0 1.57079632679" xyz="0.0 0.1131 0"/>    
    <limit effort="150" lower="-300000" upper="3000000" velocity="150000000"/>
    <dynamics damping="0.7"/>
  </joint>
  
  <link name="middle_right_coxa">
    <visual>
      <origin rpy="0.0 0.0 0.0" xyz="0.03 0 0"/>
      <geometry>
        <box size="0.06 0.01 0.02"/>
      </geometry>
      <material name="green">
        <color rgba="0 .8 0 1"/>
      </material>
    </visual>
    <collision>
      <origin rpy="0.0 0.0 0.0" xyz="0.03 0 0"/>
      <geometry>
        <box size="0.06 0.01 0.02"/>
      </geometry>
    </collision>
    <inertial>
      <origin rpy="0 0 0" xyz="0.03 0 0"/>
      <mass value="0.3"/>
      <inertia ixx="0.00364857222" ixy="5.215877e-05" ixz="0.00071534842" iyy="0.01507736897" iyz="-1.31077e-05" izz="0.01659310749"/>
    </inertial>    
  </link>
  
  <joint name="j03" type="revolute">
    <axis xyz="0 0 1"/>
    <parent link="base_link"/>
    <child link="middle_right_coxa"/>
    <origin rpy="0.0 0.0 -1.57079632679" xyz="0.0 -0.1131 0.0"/>   
    <limit effort="150" lower="-300000" upper="3000000" velocity="150000000"/>
    <dynamics damping="0.7"/>
  </joint>
  
  <link name="rear_left_coxa">
    <visual>
      <origin rpy="0.0 0.0 0.0" xyz="0.03 0 0"/>
      <geometry>
        <box size="0.06 0.01 0.02"/>
      </geometry>
      <material name="green">
        <color rgba="0 .8 0 1"/>
      </material>
    </visual>
    <collision>
      <origin rpy="0.0 0.0 0.0" xyz="0.03 0 0"/>
      <geometry>
        <box size="0.06 0.01 0.02"/>
      </geometry>
    </collision>
    <inertial>
      <origin rpy="0 0 0" xyz="0.03 0 0"/>
      <mass value="0.3"/>
      <inertia ixx="0.00364857222" ixy="5.215877e-05" ixz="0.00071534842" iyy="0.01507736897" iyz="-1.31077e-05" izz="0.01659310749"/>
    </inertial>    
  </link>
  
  <joint name="j04" type="revolute">
    <axis xyz="0 0 1"/>
    <parent link="base_link"/>
    <child link="rear_left_coxa"/>
    <origin rpy="0.0 0.0 2.35619449019" xyz="-0.1205 0.0705 0"/>    
    <limit effort="150" lower="-300000" upper="3000000" velocity="150000000"/>
    <dynamics damping="0.7"/>
  </joint>
  
  <link name="rear_right_coxa">
    <visual>
      <origin rpy="0.0 0.0 0.0" xyz="0.03 0 0"/>
      <geometry>
        <box size="0.06 0.01 0.02"/>
      </geometry>
      <material name="green">
        <color rgba="0 .8 0 1"/>
      </material>
    </visual>
    <collision>
      <origin rpy="0.0 0.0 0.0" xyz="0.03 0 0"/>
      <geometry>
        <box size="0.06 0.01 0.02"/>
      </geometry>
    </collision>
    <inertial>
      <origin rpy="0 0 0" xyz="0.03 0 0"/>
      <mass value="0.3"/>
      <inertia ixx="0.00364857222" ixy="5.215877e-05" ixz="0.00071534842" iyy="0.01507736897" iyz="-1.31077e-05" izz="0.01659310749"/>
    </inertial>    
  </link>
  
  <joint name="j05" type="revolute">
    <axis xyz="0 0 1"/>
    <parent link="base_link"/>
    <child link="rear_right_coxa"/>
    <origin rpy="0.0 0.0 -2.35619449019" xyz="-0.1205 -0.0705 0"/>    
    <limit effort="150" lower="-300000" upper="3000000" velocity="150000000"/>
    <dynamics damping="0.7"/>
  </joint-->
  
  <!--link name="front_left_femour">
    <visual>
      <origin rpy="0.0 0.0 0" xyz="0.0418 0 0"/>
      <geometry>
        <box size="0.0836 0.02 0.01"/>
      </geometry>
      <material name="orange"/>
    </visual>
    <collision>
      <origin rpy="0.0 0.0 0.0" xyz="0.0418 0 0"/>
      <geometry>
        <box size="0.0836 0.02 0.01"/>
      </geometry>
    </collision>
    <inertial>
      <origin rpy="0 0 0" xyz="0.418 0 0"/>
      <mass value="1"/>
      <inertia ixx="0.05" ixy="0" ixz="0" iyy="0.06" iyz="0" izz="0.03"/>
    </inertial>
  </link-->
  <link name="front_left_femour">
    <inertial>
      <origin rpy="0 0 0" xyz="2 0 0"/>
      <mass value="1"/>
      <inertia ixx="0.05" ixy="0" ixz="0" iyy="0.06" iyz="0" izz="0.03"/>
    </inertial>
    <visual>
      <origin rpy="0 0 0" xyz="2 0 0"/>
      <geometry>
        <box size="4 0.15 0.15"/>
      </geometry>
      <material name="red">
        <color rgba=".9 .1 .1 1"/>
      </material>
    </visual>
    <collision>
      <origin rpy="0 0 0" xyz="2 0 0"/>
      <geometry>
        <box size="4 0.15 0.15"/>
      </geometry>
      <material name="Grey"/>
    </collision>    
  </link>
  <joint name="a03" type="revolute">
    <axis xyz="0 0 1"/>
    <parent link="front_left_coxa"/>
    <child link="front_left_femour"/>
    <origin rpy="1.57079632679489661923 0.0 0.0" xyz="0.06 0 0"/>    
    <limit effort="150" lower="-300000" upper="3000000" velocity="150000000"/>
    <dynamics damping="0.7" friction="1.0"/>
  </joint>
  
</robot>
