<?xml version="1.0" ?>
<!-- =================================================================================== -->
<!-- |    This document was autogenerated by xacro from lobsang_hexapod.xacro          | -->
<!-- |    EDITING THIS FILE BY HAND IS NOT RECOMMENDED                                 | -->
<!-- =================================================================================== -->
<!-- Revolute-Revolute Manipulator -->
<robot name="hexapod" xmlns:xacro="http://www.ros.org/wiki/xacro">  
  <link name="world" />
  <link name="base_link">
    <visual>
      <origin xyz="0 0 0"/>
      <geometry>
        <box size="0.241 0.141 0.044"/>
      </geometry>
      <material name="blue"/>
    </visual>
    <collision>
      <geometry>
        <!--<box size="0.2 0.1 0.05" />-->
        <box size="0.241 0.141 0.044"/>
      </geometry>
    </collision>
    <inertial>
      <origin rpy="0 0 0" xyz="0 0 0"/>
      <mass value="1.0"/>
      <inertia ixx="0.00364857222" ixy="5.215877e-05" ixz="0.00071534842" iyy="0.01507736897" iyz="-1.31077e-05" izz="0.01659310749"/>
    </inertial>
  </link>
  <joint name="j25" type="fixed">
    <parent link="world"/>
    <child link="base_link"/>
    <origin rpy="0 0 0" xyz="0 0 0.16"/>
    <axis xyz="0 0 1"/>
    <limit effort="150" lower="-300000" upper="3000000" velocity="150000000"/>    
    <!--dynamics damping="3.0"/-->
  </joint>
  
  
  <link name="square">
    <visual>
      <origin xyz="0.0125 0 0"/>
      <geometry>
        <box size="0.025 0.025 0.025"/>
      </geometry>
      <material name="red_box">
        <color rgba=".5 0 0 1"/>
      </material>
    </visual>
    <collision>
      <geometry>
        <box size="0.025 0.025 0.025"/>
      </geometry>
    </collision>
    <inertial>
      <origin rpy="0 0 0" xyz="0 0 0"/>
      <mass value="1"/>
      <inertia ixx="0.00364857222" ixy="5.215877e-05" ixz="0.00071534842" iyy="0.01507736897" iyz="-1.31077e-05" izz="0.01659310749"/>
    </inertial>
  </link>  
  <joint name="k00" type="fixed">
    <parent link="base_link"/>
    <child link="square"/>
    <origin rpy="0.0 0.0 0.0" xyz="0.1205 0 0"/>
  </joint>
  <link name="sensor_link">
    <visual>
      <origin xyz="0.0 0 0"/>
      <geometry>
        <box size="0 0 0"/>
      </geometry>      
    </visual>
    <collision>
      <geometry>
        <box size="0 0 0"/>
      </geometry>
    </collision>    
  </link>
  <joint name="k01" type="fixed">
    <parent link="square"/>
    <child link="sensor_link"/>
    <origin rpy="0.0 0.0 0.0" xyz="0.025 0 0"/>
  </joint> 
  <link name="front_left_coxa">
    <visual>
      <origin rpy="0.0 0.0 0.0" xyz="0.03 0 0"/>
      <geometry>
        <box size="0.06 0.01 0.02"/>
      </geometry>
      <material name="green">
        <color rgba="0 .8 0 1"/>
      </material>
    </visual>
    <collision>
      <origin rpy="0.0 0.0 0.0" xyz="0.03 0 0"/>
      <geometry>
        <box size="0.06 0.01 0.02"/>
      </geometry>
    </collision>
    <inertial>
      <origin rpy="0 0 0" xyz="0.03 0 0"/>
      <mass value="0.3"/>
      <inertia ixx="0.00364857222" ixy="5.215877e-05" ixz="0.00071534842" iyy="0.01507736897" iyz="-1.31077e-05" izz="0.01659310749"/>
    </inertial>
  </link>
  <joint name="j01" type="revolute">
    <axis xyz="0 0 1"/>
    <parent link="base_link"/>
    <child link="front_left_coxa"/>
    <origin rpy="0.0 0.0 0.785398163397" xyz="0.1205 0.0705 0"/>
    <!--limit effort="10" lower="-2.4" upper="2.4" velocity="3.14159265359"/-->
    <limit effort="150" lower="-300000" upper="3000000" velocity="150000000"/>
    <dynamics damping="0.7"/>
  </joint>
  <link name="front_right_coxa">
    <visual>
      <origin rpy="0.0 0.0 0.0" xyz="0.03 0 0"/>
      <geometry>
        <box size="0.06 0.01 0.02"/>
      </geometry>
      <material name="green">
        <color rgba="0 .8 0 1"/>
      </material>
    </visual>
    <collision>
      <origin rpy="0.0 0.0 0.0" xyz="0.03 0 0"/>
      <geometry>
        <box size="0.06 0.01 0.02"/>
      </geometry>
    </collision>
    <inertial>
      <origin rpy="0 0 0" xyz="0.03 0 0"/>
      <mass value="0.3"/>
      <inertia ixx="0.00364857222" ixy="5.215877e-05" ixz="0.00071534842" iyy="0.01507736897" iyz="-1.31077e-05" izz="0.01659310749"/>
    </inertial>
  </link>
  <joint name="j02" type="revolute">
    <axis xyz="0 0 1"/>
    <parent link="base_link"/>
    <child link="front_right_coxa"/>
    <origin rpy="0.0 0.0 -0.785398163397" xyz="0.1205 -0.0705 0"/>
    <limit effort="10" lower="-2.4" upper="2.4" velocity="3.14159265359"/>
    <dynamics damping="0.7"/>
  </joint>
  <link name="middle_left_coxa">
    <visual>
      <origin rpy="0.0 0.0 0.0" xyz="0.03 0 0"/>
      <geometry>
        <box size="0.06 0.01 0.02"/>
      </geometry>
      <material name="green">
        <color rgba="0 .8 0 1"/>
      </material>
    </visual>
    <collision>
      <origin rpy="0.0 0.0 0.0" xyz="0.03 0 0"/>
      <geometry>
        <box size="0.06 0.01 0.02"/>
      </geometry>
    </collision>
    <inertial>
      <origin rpy="0 0 0" xyz="0.03 0 0"/>
      <mass value="0.3"/>
      <inertia ixx="0.00364857222" ixy="5.215877e-05" ixz="0.00071534842" iyy="0.01507736897" iyz="-1.31077e-05" izz="0.01659310749"/>
    </inertial>
  </link>
  <joint name="j03" type="revolute">
    <axis xyz="0 0 1"/>
    <parent link="base_link"/>
    <child link="middle_left_coxa"/>
    <origin rpy="0.0 0.0 1.57079632679" xyz="0.0 0.1131 0"/>
    <limit effort="10" lower="-2.4" upper="2.4" velocity="3.14159265359"/>
    <dynamics damping="0.7"/>
  </joint>
  <link name="middle_right_coxa">
    <visual>
      <origin rpy="0.0 0.0 0.0" xyz="0.03 0 0"/>
      <geometry>
        <box size="0.06 0.01 0.02"/>
      </geometry>
      <material name="green">
        <color rgba="0 .8 0 1"/>
      </material>
    </visual>
    <collision>
      <origin rpy="0.0 0.0 0.0" xyz="0.03 0 0"/>
      <geometry>
        <box size="0.06 0.01 0.02"/>
      </geometry>
    </collision>
    <inertial>
      <origin rpy="0 0 0" xyz="0.03 0 0"/>
      <mass value="0.3"/>
      <inertia ixx="0.00364857222" ixy="5.215877e-05" ixz="0.00071534842" iyy="0.01507736897" iyz="-1.31077e-05" izz="0.01659310749"/>
    </inertial>
  </link>
  <joint name="j04" type="revolute">
    <axis xyz="0 0 1"/>
    <parent link="base_link"/>
    <child link="middle_right_coxa"/>
    <origin rpy="0.0 0.0 -1.57079632679" xyz="0.0 -0.1131 0.0"/>
    <limit effort="10" lower="-2.4" upper="2.4" velocity="3.14159265359"/>
    <dynamics damping="0.7"/>
  </joint>
  <link name="rear_left_coxa">
    <visual>
      <origin rpy="0.0 0.0 0.0" xyz="0.03 0 0"/>
      <geometry>
        <box size="0.06 0.01 0.02"/>
      </geometry>
      <material name="green">
        <color rgba="0 .8 0 1"/>
      </material>
    </visual>
    <collision>
      <origin rpy="0.0 0.0 0.0" xyz="0.03 0 0"/>
      <geometry>
        <box size="0.06 0.01 0.02"/>
      </geometry>
    </collision>
    <inertial>
      <origin rpy="0 0 0" xyz="0.03 0 0"/>
      <mass value="0.3"/>
      <inertia ixx="0.00364857222" ixy="5.215877e-05" ixz="0.00071534842" iyy="0.01507736897" iyz="-1.31077e-05" izz="0.01659310749"/>
    </inertial>
  </link>
  <joint name="j05" type="revolute">
    <axis xyz="0 0 1"/>
    <parent link="base_link"/>
    <child link="rear_left_coxa"/>
    <origin rpy="0.0 0.0 2.35619449019" xyz="-0.1205 0.0705 0"/>
    <limit effort="10" lower="-2.4" upper="2.4" velocity="3.14159265359"/>
    <dynamics damping="0.7"/>
  </joint>
  <link name="rear_right_coxa">
    <visual>
      <origin rpy="0.0 0.0 0.0" xyz="0.03 0 0"/>
      <geometry>
        <box size="0.06 0.01 0.02"/>
      </geometry>
      <material name="green">
        <color rgba="0 .8 0 1"/>
      </material>
    </visual>
    <collision>
      <origin rpy="0.0 0.0 0.0" xyz="0.03 0 0"/>
      <geometry>
        <box size="0.06 0.01 0.02"/>
      </geometry>
    </collision>
    <inertial>
      <origin rpy="0 0 0" xyz="0.03 0 0"/>
      <mass value="0.3"/>
      <inertia ixx="0.00364857222" ixy="5.215877e-05" ixz="0.00071534842" iyy="0.01507736897" iyz="-1.31077e-05" izz="0.01659310749"/>
    </inertial>
  </link>
  <joint name="j06" type="revolute">
    <axis xyz="0 0 1"/>
    <parent link="base_link"/>
    <child link="rear_right_coxa"/>
    <origin rpy="0.0 0.0 -2.35619449019" xyz="-0.1205 -0.0705 0"/>
    <limit effort="10" lower="-2.4" upper="2.4" velocity="3.14159265359"/>
    <dynamics damping="0.7"/>
  </joint>
  <link name="front_left_femour">
    <visual>
      <origin rpy="0.0 0.0 0" xyz="0.0418 0 0"/>
      <geometry>
        <box size="0.0836 0.02 0.01"/>
      </geometry>
      <material name="orange"/>
    </visual>
    <collision>
      <origin rpy="0.0 0.0 0.0" xyz="0.0418 0 0"/>
      <geometry>
        <box size="0.0836 0.02 0.01"/>
      </geometry>
    </collision>
    <inertial>
      <origin rpy="0 0 0" xyz="0.0418 0 0"/>
      <mass value="0.3"/>
      <inertia ixx="0.00364857222" ixy="5.215877e-05" ixz="0.00071534842" iyy="0.01507736897" iyz="-1.31077e-05" izz="0.01659310749"/>
    </inertial>
  </link>
  <joint name="j07" type="revolute">
    <axis xyz="0 0 1"/>
    <parent link="front_left_coxa"/>
    <child link="front_left_femour"/>
    <origin rpy="1.57079632679489661923 0.0 0.0" xyz="0.06 0 0"/>
    <!--limit effort="10" lower="-2.4" upper="2.4" velocity="3.14159265359"/-->
    <limit effort="150" lower="-300000" upper="3000000" velocity="150000000"/>
    <dynamics damping="0.7" friction="1.0"/>
  </joint>
  <link name="front_right_femour">
    <visual>
      <origin rpy="0.0 0.0 0" xyz="0.0418 0 0"/>
      <geometry>
        <box size="0.0836 0.02 0.01"/>
      </geometry>
      <material name="orange"/>
    </visual>
    <collision>
      <origin rpy="0.0 0.0 0.0" xyz="0.0418 0 0"/>
      <geometry>
        <box size="0.0836 0.02 0.01"/>
      </geometry>
    </collision>
    <inertial>
      <origin rpy="0 0 0" xyz="0.0418 0 0"/>
      <mass value="0.3"/>
      <inertia ixx="0.00364857222" ixy="5.215877e-05" ixz="0.00071534842" iyy="0.01507736897" iyz="-1.31077e-05" izz="0.01659310749"/>
    </inertial>
  </link>
  <joint name="j08" type="revolute">
    <axis xyz="0 0 1"/>
    <parent link="front_right_coxa"/>
    <child link="front_right_femour"/>
    <origin rpy="-1.57079632679489661923 0.0 0.0" xyz="0.06 0 0"/>
    <limit effort="10" lower="-2.4" upper="2.4" velocity="3.14159265359"/>
    <dynamics damping="0.7"/>
  </joint>
  <link name="middle_left_femour">
    <visual>
      <origin rpy="0.0 0.0 0" xyz="0.0418 0 0"/>
      <geometry>
        <box size="0.0836 0.02 0.01"/>
      </geometry>
      <material name="orange"/>
    </visual>
    <collision>
      <origin rpy="0.0 0.0 0.0" xyz="0.0418 0 0"/>
      <geometry>
        <box size="0.0836 0.02 0.01"/>
      </geometry>
    </collision>
    <inertial>
      <origin rpy="0 0 0" xyz="0.0418 0 0"/>
      <mass value="0.3"/>
      <inertia ixx="0.00364857222" ixy="5.215877e-05" ixz="0.00071534842" iyy="0.01507736897" iyz="-1.31077e-05" izz="0.01659310749"/>
    </inertial>
  </link>
  <joint name="j09" type="revolute">
    <axis xyz="0 0 1"/>
    <parent link="middle_left_coxa"/>
    <child link="middle_left_femour"/>
    <origin rpy="1.57079632679489661923 0.0 0.0" xyz="0.06 0 0"/>
    <limit effort="10" lower="-2.4" upper="2.4" velocity="3.14159265359"/>
    <dynamics damping="0.7"/>
  </joint>
  <link name="middle_right_femour">
    <visual>
      <origin rpy="0.0 0.0 0" xyz="0.0418 0 0"/>
      <geometry>
        <box size="0.0836 0.02 0.01"/>
      </geometry>
      <material name="orange"/>
    </visual>
    <collision>
      <origin rpy="0.0 0.0 0.0" xyz="0.0418 0 0"/>
      <geometry>
        <box size="0.0836 0.02 0.01"/>
      </geometry>
    </collision>
    <inertial>
      <origin rpy="0 0 0" xyz="0.0418 0 0"/>
      <mass value="0.3"/>
      <inertia ixx="0.00364857222" ixy="5.215877e-05" ixz="0.00071534842" iyy="0.01507736897" iyz="-1.31077e-05" izz="0.01659310749"/>
    </inertial>
  </link>
  <joint name="j10" type="revolute">
    <axis xyz="0 0 1"/>
    <parent link="middle_right_coxa"/>
    <child link="middle_right_femour"/>
    <origin rpy="-1.57079632679489661923 0.0 0.0" xyz="0.06 0 0"/>
    <limit effort="10" lower="-2.4" upper="2.4" velocity="3.14159265359"/>
    <dynamics damping="0.7"/>
  </joint>
  <link name="rear_left_femour">
    <visual>
      <origin rpy="0.0 0.0 0" xyz="0.0418 0 0"/>
      <geometry>
        <box size="0.0836 0.02 0.01"/>
      </geometry>
      <material name="orange"/>
    </visual>
    <collision>
      <origin rpy="0.0 0.0 0.0" xyz="0.0418 0 0"/>
      <geometry>
        <box size="0.0836 0.02 0.01"/>
      </geometry>
    </collision>
    <inertial>
      <origin rpy="0 0 0" xyz="0.0418 0 0"/>
      <mass value="0.3"/>
      <inertia ixx="0.00364857222" ixy="5.215877e-05" ixz="0.00071534842" iyy="0.01507736897" iyz="-1.31077e-05" izz="0.01659310749"/>
    </inertial>
  </link>
  <joint name="j11" type="revolute">
    <axis xyz="0 0 1"/>
    <parent link="rear_left_coxa"/>
    <child link="rear_left_femour"/>
    <origin rpy="1.57079632679489661923 0.0 0.0" xyz="0.06 0 0"/>
    <limit effort="10" lower="-2.4" upper="2.4" velocity="3.14159265359"/>
    <dynamics damping="0.7"/>
  </joint>
  <link name="rear_right_femour">
    <visual>
      <origin rpy="0.0 0.0 0" xyz="0.0418 0 0"/>
      <geometry>
        <box size="0.0836 0.02 0.01"/>
      </geometry>
      <material name="orange"/>
    </visual>
    <collision>
      <origin rpy="0.0 0.0 0.0" xyz="0.0418 0 0"/>
      <geometry>
        <box size="0.0836 0.02 0.01"/>
      </geometry>
    </collision>
    <inertial>
      <origin rpy="0 0 0" xyz="0.0418 0 0"/>
      <mass value="0.3"/>
      <inertia ixx="0.00364857222" ixy="5.215877e-05" ixz="0.00071534842" iyy="0.01507736897" iyz="-1.31077e-05" izz="0.01659310749"/>
    </inertial>
  </link>
  <joint name="j12" type="revolute">
    <axis xyz="0 0 1"/>
    <parent link="rear_right_coxa"/>
    <child link="rear_right_femour"/>
    <origin rpy="-1.57079632679489661923 0.0 0.0" xyz="0.06 0 0"/>
    <limit effort="10" lower="-2.4" upper="2.4" velocity="3.14159265359"/>
    <dynamics damping="0.7"/>
  </joint>
  <link name="front_left_tibia">
    <visual>
      <origin rpy="0.0 0.0 0.0" xyz="0.1 0 0"/>
      <geometry>
        <box size="0.2 0.01 0.01"/>
      </geometry>
      <material name="red"/>
    </visual>
    <collision>
      <origin rpy="0.0 0.0 0.0" xyz="0.1 0 0"/>
      <geometry>
        <box size="0.2 0.01 0.01"/>
      </geometry>
    </collision>
    <inertial>
      <origin rpy="0 0 0" xyz="0.1 0 0"/>
      <mass value="0.3"/>
      <inertia ixx="0.00364857222" ixy="5.215877e-05" ixz="0.00071534842" iyy="0.01507736897" iyz="-1.31077e-05" izz="0.01659310749"/>
    </inertial>
  </link>
  <joint name="j13" type="revolute">
    <axis xyz="0 0 1"/>
    <parent link="front_left_femour"/>
    <child link="front_left_tibia"/>
    <origin rpy="0.0 0.0 0.0" xyz="0.0836 0 0"/>
    <limit effort="10" lower="-2.4" upper="2.4" velocity="3.14159265359"/>
    <dynamics damping="0.7"/>
  </joint>
  <link name="front_right_tibia">
    <visual>
      <origin rpy="0.0 0.0 0.0" xyz="0.1 0 0"/>
      <geometry>
        <box size="0.2 0.01 0.01"/>
      </geometry>
      <material name="red"/>
    </visual>
    <collision>
      <origin rpy="0.0 0.0 0.0" xyz="0.1 0 0"/>
      <geometry>
        <box size="0.2 0.01 0.01"/>
      </geometry>
    </collision>
    <inertial>
      <origin rpy="0 0 0" xyz="0.1 0 0"/>
      <mass value="0.3"/>
      <inertia ixx="0.00364857222" ixy="5.215877e-05" ixz="0.00071534842" iyy="0.01507736897" iyz="-1.31077e-05" izz="0.01659310749"/>
    </inertial>
  </link>
  <joint name="j14" type="revolute">
    <axis xyz="0 0 1"/>
    <parent link="front_right_femour"/>
    <child link="front_right_tibia"/>
    <origin rpy="0.0 0.0 0.0" xyz="0.0836 0 0"/>
    <limit effort="10" lower="-2.4" upper="2.4" velocity="3.14159265359"/>
    <dynamics damping="0.7"/>
  </joint>
  <link name="middle_left_tibia">
    <visual>
      <origin rpy="0.0 0.0 0.0" xyz="0.1 0 0"/>
      <geometry>
        <box size="0.2 0.01 0.01"/>
      </geometry>
      <material name="red"/>
    </visual>
    <collision>
      <origin rpy="0.0 0.0 0.0" xyz="0.1 0 0"/>
      <geometry>
        <box size="0.2 0.01 0.01"/>
      </geometry>
    </collision>
    <inertial>
      <origin rpy="0 0 0" xyz="0.1 0 0"/>
      <mass value="0.3"/>
      <inertia ixx="0.00364857222" ixy="5.215877e-05" ixz="0.00071534842" iyy="0.01507736897" iyz="-1.31077e-05" izz="0.01659310749"/>
    </inertial>
  </link>
  <joint name="j15" type="revolute">
    <axis xyz="0 0 1"/>
    <parent link="middle_left_femour"/>
    <child link="middle_left_tibia"/>
    <origin rpy="0.0 0.0 0.0" xyz="0.0836 0 0"/>
    <limit effort="10" lower="-2.4" upper="2.4" velocity="3.14159265359"/>
    <dynamics damping="0.7"/>
  </joint>
  <link name="middle_right_tibia">
    <visual>
      <origin rpy="0.0 0.0 0.0" xyz="0.1 0 0"/>
      <geometry>
        <box size="0.2 0.01 0.01"/>
      </geometry>
      <material name="red"/>
    </visual>
    <collision>
      <origin rpy="0.0 0.0 0.0" xyz="0.1 0 0"/>
      <geometry>
        <box size="0.2 0.01 0.01"/>
      </geometry>
    </collision>
    <inertial>
      <origin rpy="0 0 0" xyz="0.1 0 0"/>
      <mass value="0.3"/>
      <inertia ixx="0.00364857222" ixy="5.215877e-05" ixz="0.00071534842" iyy="0.01507736897" iyz="-1.31077e-05" izz="0.01659310749"/>
    </inertial>
  </link>
  <joint name="j16" type="revolute">
    <axis xyz="0 0 1"/>
    <parent link="middle_right_femour"/>
    <child link="middle_right_tibia"/>
    <origin rpy="0.0 0.0 0.0" xyz="0.0836 0 0"/>
    <limit effort="10" lower="-2.4" upper="2.4" velocity="3.14159265359"/>
    <dynamics damping="0.7"/>
  </joint>
  <link name="rear_left_tibia">
    <visual>
      <origin rpy="0.0 0.0 0.0" xyz="0.1 0 0"/>
      <geometry>
        <box size="0.2 0.01 0.01"/>
      </geometry>
      <material name="red"/>
    </visual>
    <collision>
      <origin rpy="0.0 0.0 0.0" xyz="0.1 0 0"/>
      <geometry>
        <box size="0.2 0.01 0.01"/>
      </geometry>
    </collision>
    <inertial>
      <origin rpy="0 0 0" xyz="0.1 0 0"/>
      <mass value="0.3"/>
      <inertia ixx="0.00364857222" ixy="5.215877e-05" ixz="0.00071534842" iyy="0.01507736897" iyz="-1.31077e-05" izz="0.01659310749"/>
    </inertial>
  </link>
  <joint name="j17" type="revolute">
    <axis xyz="0 0 1"/>
    <parent link="rear_left_femour"/>
    <child link="rear_left_tibia"/>
    <origin rpy="0.0 0.0 0.0" xyz="0.0836 0 0"/>
    <limit effort="10" lower="-2.4" upper="2.4" velocity="3.14159265359"/>
    <dynamics damping="0.7"/>
  </joint>
  <link name="rear_right_tibia">
    <visual>
      <origin rpy="0.0 0.0 0.0" xyz="0.1 0 0"/>
      <geometry>
        <box size="0.2 0.01 0.01"/>
      </geometry>
      <material name="red"/>
    </visual>
    <collision>
      <origin rpy="0.0 0.0 0.0" xyz="0.1 0 0"/>
      <geometry>
        <box size="0.2 0.01 0.01"/>
      </geometry>
    </collision>
    <inertial>
      <origin rpy="0 0 0" xyz="0.1 0 0"/>
      <mass value="0.3"/>
      <inertia ixx="0.00364857222" ixy="5.215877e-05" ixz="0.00071534842" iyy="0.01507736897" iyz="-1.31077e-05" izz="0.01659310749"/>
    </inertial>
  </link>
  <joint name="j18" type="revolute">
    <axis xyz="0 0 1"/>
    <parent link="rear_right_femour"/>
    <child link="rear_right_tibia"/>
    <origin rpy="0.0 0.0 0.0" xyz="0.0836 0 0"/>
    <limit effort="10" lower="-2.4" upper="2.4" velocity="3.14159265359"/>
    <dynamics damping="0.7"/>
  </joint>
  <link name="front_left_end_effector">
    <visual>
      <origin rpy="0.0 0.0 0.0" xyz="0.0 0 0"/>
      <geometry>
        <box size="0.0 0.0 0.0"/>
      </geometry>
    </visual>
  </link>
  <joint name="j19" type="fixed">
    <axis xyz="0 0 1"/>
    <parent link="front_left_tibia"/>
    <child link="front_left_end_effector"/>
    <origin rpy="0.0 0.0 0.0" xyz="0.2 0 0"/>
    <limit effort="10" lower="-2.4" upper="2.4" velocity="3.14159265359"/>
  </joint>
  <link name="front_right_end_effector">
    <visual>
      <origin rpy="0.0 0.0 0.0" xyz="0.0 0 0"/>
      <geometry>
        <box size="0.0 0.0 0.0"/>
      </geometry>
    </visual>
  </link>
  <joint name="j20" type="fixed">
    <axis xyz="0 0 1"/>
    <parent link="front_right_tibia"/>
    <child link="front_right_end_effector"/>
    <origin rpy="0.0 0.0 0.0" xyz="0.2 0 0"/>
    <limit effort="10" lower="-2.4" upper="2.4" velocity="3.14159265359"/>
  </joint>
  <link name="middle_left_end_effector">
    <visual>
      <origin rpy="0.0 0.0 0.0" xyz="0.0 0 0"/>
      <geometry>
        <box size="0.0 0.0 0.0"/>
      </geometry>
    </visual>
  </link>
  <joint name="j21" type="fixed">
    <axis xyz="0 0 1"/>
    <parent link="middle_left_tibia"/>
    <child link="middle_left_end_effector"/>
    <origin rpy="0.0 0.0 0.0" xyz="0.2 0 0"/>
    <limit effort="10" lower="-2.4" upper="2.4" velocity="3.14159265359"/>
  </joint>
  <link name="middle_right_end_effector">
    <visual>
      <origin rpy="0.0 0.0 0.0" xyz="0.0 0 0"/>
      <geometry>
        <box size="0.0 0.0 0.0"/>
      </geometry>
    </visual>
  </link>
  <joint name="j22" type="fixed">
    <axis xyz="0 0 1"/>
    <parent link="middle_right_tibia"/>
    <child link="middle_right_end_effector"/>
    <origin rpy="0.0 0.0 0.0" xyz="0.2 0 0"/>
    <limit effort="10" lower="-2.4" upper="2.4" velocity="3.14159265359"/>
  </joint>
  <link name="rear_left_end_effector">
    <visual>
      <origin rpy="0.0 0.0 0.0" xyz="0.0 0 0"/>
      <geometry>
        <box size="0.0 0.0 0.0"/>
      </geometry>
    </visual>
  </link>
  <joint name="j23" type="fixed">
    <axis xyz="0 0 1"/>
    <parent link="rear_left_tibia"/>
    <child link="rear_left_end_effector"/>
    <origin rpy="0.0 0.0 0.0" xyz="0.2 0 0"/>
    <limit effort="10" lower="-2.4" upper="2.4" velocity="3.14159265359"/>
  </joint>
  <link name="rear_right_end_effector">
    <visual>
      <origin rpy="0.0 0.0 0.0" xyz="0.0 0 0"/>
      <geometry>
        <box size="0.0 0.0 0.0"/>
      </geometry>
    </visual>
  </link>
  <joint name="j24" type="fixed">
    <axis xyz="0 0 1"/>
    <parent link="rear_right_tibia"/>
    <child link="rear_right_end_effector"/>
    <origin rpy="0.0 0.0 0.0" xyz="0.2 0 0"/>
    <limit effort="10" lower="-2.4" upper="2.4" velocity="3.14159265359"/>
  </joint>
</robot>

